Workbook

Sheet 说明与检查
A1: 星链数科（模拟 fintech 公司）— Excel 三表联动模型 v4 · 说明与检查
A2: 单位：人民币元 | 基年 2025A | 预测期 2026E–2030E | 打开本页即可看到模型结论与自动勾稽状态
A3: 【30 秒速览】
A4: 是什么 | B4: 一个 6 年（2025A + 2026E–2030E）三表联动模型：利润表 / 资产负债表 / 现金流量表全公式咬合，含债务排程与简化 DCF，改一个假设全簿重算。
A5: 怎么演示 | B5: 「假设」页顶部下拉框切 Base / Bull / Bear → 三表、债务排程、图表、敏感性结论同步变；本页 6 项勾稽始终显示 ✓。
A6: 核心数字 | B6: ="2027E 净利润 "&TEXT(利润表!$D$13/10000,"0.0")&" 万元 · 2030E 期末现金 "&TEXT(现金流量表!$G$20/10000,"0.0")&" 万元 · 股权价值 "&TEXT(敏感性分析!$C$15/10000,"0.0")&" 万元 · 最小利息保障 "&TEXT(MIN(支持排程!$C$16:$G$16),"0.0")&"x" -> 2027E 净利润 13.1 万元 · 2030E 期末现金 636.8 万元 · 股权价值 997.9 万元 · 最小利息保障 2.0x
A8: 核心结论看板（随「假设」页情景自动重算）
A9: 当前情景 | B9: =假设!$B$3 -> Base
A10: 收入增长率 / 毛利率 | B10: =TEXT(假设!$C$5,"0.0%")&" / "&TEXT(假设!$C$6,"0.0%") -> 5.0% / 60.0%
A11: 2027E 净利润（万元） | B11: =利润表!$D$13/10000 -> 13.096875
A12: 2027E 期末现金（万元） | B12: =现金流量表!$D$20/10000 -> 927.00312
A13: 2030E 期末现金（万元） | B13: =现金流量表!$G$20/10000 -> 636.79945
A14: 5 年累计净利润（2026E–2030E，万元） | B14: =SUM(利润表!$C$13:$G$13)/10000 -> 89.311956
A15: 增长率每 +1pp → 5 年累计净利润（万元） | B15: =敏感性分析!$C$45 -> 5.2021718
A16: 股权价值（简化DCF，万元） | B16: =敏感性分析!$C$15/10000 -> 997.89373
A17: 2030E 有息负债余额（万元） | B17: =支持排程!$G$8/10000 -> 50
A18: 最小利息保障倍数（2026E–2030E） | B18: =MIN(支持排程!$C$16:$G$16) -> 2.0348148
A19: 现金安全预警 | B19: =IF(MIN(现金流量表!$C$20:$G$20)<假设!$C$14,"⚠ 预测期内现金低于安全线：最低 "&TEXT(MIN(现金流量表!$C$20:$G$20),"#,##0")&" 元，安全垫 "&TEXT(MIN(现金流量表!$C$20:$G$20)-假设!$C$14,"#,##0")&" 元","✓ 预测期内现金始终高于安全线，最低 "&TEXT(MIN(现金流量表!$C$20:$G$20),"#,##0")&" 元，安全垫 "&TEXT(MIN(现金流量表!$C$20:$G$20)-假设!$C$14,"#,##0")&" 元") -> ✓ 预测期内现金始终高于安全线，最低 6,367,995 元，安全垫 2,367,995 元
A20: 三表勾稽状态 | B20: =IF(AND(COUNTIF(资产负债表!$B$21:$G$21,"平衡")=6,COUNTIF(资产负债表!$B$23:$G$23,"平衡")=6,SUMPRODUCT(ABS(利润表!$B$13:$G$13-现金流量表!$B$5:$G$5))<0.01,SUMPRODUCT(ABS(资产负债表!$C$15:$G$15-(资产负债表!$B$15:$F$15+利润表!$C$13:$G$13)))<0.01,SUMPRODUCT(ABS(资产负债表!$B$11:$G$11-支持排程!$B$8:$G$8))<0.01,SUMPRODUCT(ABS(利润表!$B$10:$G$10-支持排程!$B$10:$G$10))<0.01),"✓ 6 项检查全部通过：三表 + 债务排程联动无断点","✗ 存在不平衡，请检查") -> ✓ 6 项检查全部通过：三表 + 债务排程联动无断点
A22: 演示动线（面试 3 步走，建议提前演练）
A23: ① 打开本页：看上方【30 秒速览】与“核心结论看板”，再看下方“自动勾稽检查”6 项全部 ✓，说明三表 + 债务排程联动无断点。
A24: ② 打开「假设」页，把顶部“情景切换”下拉框从 Base 切到 Bull（增长率 5%→10%、毛利率 60%→65%），口头说：“我只改了这一个下拉框。”
A25: ③ 切到「利润表 / 资产负债表 / 现金流量表」看三表同步变化 → 「支持排程」看债务与固定资产滚动及 ROIC → 「图表」看趋势图与现金跑道重绘 → 「敏感性分析」第六节看三情景并排对比表与动态结论句自动改写。
A26: ④ 打开「支持排程」页，修改蓝色“新增借款 / 偿还本金”——利息费用、资产负债率、利息保障倍数、筹资现金流、期末现金全部联动（利息 = 平均余额 × 利率，无循环引用）。
A27: 提示：自定义情景请改「假设」页第 26–28 行的驱动因子映射表（蓝色单元格）；直接改正式假设区数值会覆盖情景联动。
A29: 自动勾稽检查
A30: ① 资产 = 负债 + 权益（全部 6 年） | B30: =IF(COUNTIF(资产负债表!$B$21:$G$21,"平衡")=6,"✓ 全部平衡（6/6）","✗ 存在不平衡") -> ✓ 全部平衡（6/6）
A31: ② 现金勾稽：本表现金 = 现金流量表期末现金（6 年） | B31: =IF(COUNTIF(资产负债表!$B$23:$G$23,"平衡")=6,"✓ 全部平衡（6/6）","✗ 存在不平衡") -> ✓ 全部平衡（6/6）
A32: ③ 净利润联动：利润表净利润 = 现金流量表起点 | B32: =IF(SUMPRODUCT(ABS(利润表!$B$13:$G$13-现金流量表!$B$5:$G$5))<0.01,"✓ 完全联动","✗ 存在断点") -> ✓ 完全联动
A33: ④ 留存收益滚动：上年留存 + 净利润 = 本年留存（预测年） | B33: =IF(SUMPRODUCT(ABS(资产负债表!$C$15:$G$15-(资产负债表!$B$15:$F$15+利润表!$C$13:$G$13)))<0.01,"✓ 滚动正确","✗ 存在断点") -> ✓ 滚动正确
A34: ⑤ 有息负债联动：资产负债表 = 债务排程期末余额（6 年） | B34: =IF(SUMPRODUCT(ABS(资产负债表!$B$11:$G$11-支持排程!$B$8:$G$8))<0.01,"✓ 完全联动","✗ 存在断点") -> ✓ 完全联动
A35: ⑥ 利息联动：利润表利息费用 = 债务排程利息（6 年） | B35: =IF(SUMPRODUCT(ABS(利润表!$B$10:$G$10-支持排程!$B$10:$G$10))<0.01,"✓ 完全联动","✗ 存在断点") -> ✓ 完全联动
A37: 模型地图（Sheet 关系图 · 文字版）
A38: 【假设】——情景切换 + 蓝色输入，是全簿唯一数据入口：驱动 →【利润表】【资产负债表】【现金流量表】
A39: 【支持排程】——债务排程 / 固定资产排程：利息费用 → 利润表；有息负债、固定资产净值 → 资产负债表；偿付利息、新增借款 → 现金流量表
A40: 【图表】← 读取 ——【利润表 / 资产负债表 / 现金流量表 / 支持排程】：4 张图（收入与净利润、现金跑道 vs 安全线、债务余额与利息保障倍数、资产负债结构）
A41: 【敏感性分析】← 读取 —— 全簿：增长率 × 毛利率双变量（①）、边际敏感度（②）、股权价值分解（③）、三情景并排对比（第六节）
A42: 【说明与检查】（本页）← 汇总 —— 全簿：30 秒速览 + 核心看板 + 模型地图 + 6 项勾稽
A43: 数据流单向：假设 → 报表 → 排程 / 图表 / 敏感性；唯一天然回路“利息 ⇄ 现金”用平均余额法显式解开，全簿无循环引用。
A46: 使用方法与模型逻辑
...

Sheet 假设
A1: 星链数科（模拟 fintech 公司）— 假设面板（模型主控台）
A2: 单位：人民币元 | 基年 2025A（蓝色实际数）| 预测期 2026E–2030E | 切换顶部情景 → 三张报表 + 支持排程 + 图表 + 敏感性分析全部联动重算
A3: ① 情景切换（主控台） | B3: Base | C3: 下拉选择：Base / Bull / Bear → 自动切换下方增长率与毛利率
A4: 编号 | B4: 假设项 | C4: 数值 | D4: 单位 | E4: 数据验证 | F4: 影响范围
A5: A-01 | B5: 收入增长率 | C5: =INDEX($B$26:$B$28,MATCH($B$3,$A$26:$A$28,0)) -> 0.05 | D5: % | E5: 情景联动（Base/Bull/Bear） | F5: 收入、客户数、毛利、净利润、留存收益、现金
A6: A-02 | B6: 毛利率 | C6: =INDEX($C$26:$C$28,MATCH($B$3,$A$26:$A$28,0)) -> 0.6 | D6: % | E6: 情景联动（Base/Bull/Bear） | F6: 毛利、税前利润、净利润
A7: A-03 | B7: 获客成本 CAC | C7: 200 | D7: 元/客户 | E7: 数值：100–500 | F7: 运营成本、净利润
A8: A-04 | B8: 企业所得税率 | C8: 0.25 | D8: % | E8: 数值：0%–35% | F8: 所得税费用、净利润
A9: A-05 | B9: 折现率 | C9: 0.1 | D9: % | E9: 数值：5%–20% | F9: 估值（见敏感性分析）
A10: A-06 | B10: 客户数（基年） | C10: 1000 | D10: 户 | E10: 数值：1–100,000 | F10: 客户数、运营成本、净利润
A11: A-07 | B11: 年资本支出 | C11: 100000 | D11: 元/年 | E11: 数值：0–1,000,000 | F11: 投资现金流、固定资产原值与净值、期末现金
A12: A-08 | B12: 应收账款占收入比 | C12: 0.1 | D12: % | E12: 数值：0%–50% | F12: 应收账款、营运资本、经营现金流
A13: A-09 | B13: 应付账款占收入比 | C13: 0.05 | D13: % | E13: 数值：0%–50% | F13: 应付账款、营运资本、经营现金流
A14: A-10 | B14: 现金安全线 | C14: 4000000 | D14: 元 | E14: 数值：0–10,000,000 | F14: 现金跑道图预警线
A15: A-11 | B15: 借款年利率 | C15: 0.045 | D15: % | E15: 数值：0%–15% | F15: 利息费用、税前利润、净利润、偿债能力指标
A16: A-12 | B16: 折旧率（按固定资产净值） | C16: 0.05 | D16: % | E16: 数值：0%–20% | F16: 折旧、税前利润、固定资产净值、经营现金流
A18: 颜色规范：蓝色字体 = 可修改输入；黑色字体 = 本表公式计算；绿色字体 = 跨表引用；浅蓝底 = 受情景切换器驱动或校验区。
A19: ① 情景切换：顶部下拉框切换 Base / Bull / Bear，自动改变收入增长率与毛利率；其余假设沿用默认值，可单独覆盖。
A20: ② 驱动因子映射表位于本表下方（可见可改）：三情景的增长率/毛利率均带数据验证，改数值即可自定义情景。
A21: ③ 债务与折旧排程集中在「支持排程」页：新增借款/偿还本金为蓝色融资计划输入；利息 = 平均有息负债 × 年利率（A-11），当年全额付现，不构成循环引用。
A22: ④ 折旧按固定资产期初净值 × 折旧率（A-12）计提，并以期初净值为上限，不会折成负值；原值/净值/累计折旧滚动见「支持排程」页。
A23: ⑤ 所有预测单元格均为公式、无硬编码——改任一项，利润表 / 资产负债表 / 现金流量表 / 支持排程 / 图表 / 敏感性分析同步联动。
A24: ② 驱动因子映射表（情景切换器数据源 · 蓝色可直接修改）
A25: 情景 | B25: 收入增长率 | C25: 毛利率
A26: Base | B26: 0.05 | C26: 0.6
A27: Bull | B27: 0.1 | C27: 0.65
A28: Bear | B28: 0.03 | C28: 0.55

Sheet 利润表
A1: 星链数科 — 利润表（Income Statement）
A2: 单位：元 | 2025A 为基年实际数（蓝色），2026E–2030E 由假设面板情景驱动；利息费用来自「支持排程」债务排程
A3: 项目 | B3: 2025A | C3: 2026E | D3: 2027E | E3: 2028E | F3: 2029E | G3: 2030E
A4: 客户数（期末，户） | B4: =假设!$C$10 -> 1000 | C4: =B4*(1+假设!$C$5) -> 1050 | D4: =C4*(1+假设!$C$5) -> 1102.5 | E4: =D4*(1+假设!$C$5) -> 1157.625 | F4: =E4*(1+假设!$C$5) -> 1215.5062 | G4: =F4*(1+假设!$C$5) -> 1276.2816
A5: 营业收入 | B5: 1000000 | C5: =B5*(1+假设!$C$5) -> 1050000 | D5: =C5*(1+假设!$C$5) -> 1102500 | E5: =D5*(1+假设!$C$5) -> 1157625 | F5: =E5*(1+假设!$C$5) -> 1215506.2 | G5: =F5*(1+假设!$C$5) -> 1276281.6
A6: 毛利 | B6: 600000 | C6: =C5*假设!$C$6 -> 630000 | D6: =D5*假设!$C$6 -> 661500 | E6: =E5*假设!$C$6 -> 694575 | F6: =F5*假设!$C$6 -> 729303.75 | G6: =G5*假设!$C$6 -> 765768.94
A7: 运营成本（获客：客户数×CAC） | B7: 200000 | C7: =C4*假设!$C$7 -> 210000 | D7: =D4*假设!$C$7 -> 220500 | E7: =E4*假设!$C$7 -> 231525 | F7: =F4*假设!$C$7 -> 243101.25 | G7: =G4*假设!$C$7 -> 255256.31
A8: 折旧（支持排程·按净值计提） | B8: 100000 | C8: =支持排程!C23 -> 97500 | D8: =支持排程!D23 -> 97625 | E8: =支持排程!E23 -> 97743.75 | F8: =支持排程!F23 -> 97856.562 | G8: =支持排程!G23 -> 97963.734
A9: 息税前利润 EBIT | B9: =B6-B7-B8 -> 300000 | C9: =C6-C7-C8 -> 322500 | D9: =D6-D7-D8 -> 343375 | E9: =E6-E7-E8 -> 365306.25 | F9: =F6-F7-F8 -> 388345.94 | G9: =G6-G7-G8 -> 412548.89
A10: 减：利息费用（平均有息负债×利率） | B10: =支持排程!B10 -> 45000 | C10: =支持排程!C10 -> 123750 | D10: =支持排程!D10 -> 168750 | E10: =支持排程!E10 -> 168750 | F10: =支持排程!F10 -> 123750 | G10: =支持排程!G10 -> 56250
A11: 税前利润 | B11: =B9-B10 -> 255000 | C11: =C9-C10 -> 198750 | D11: =D9-D10 -> 174625 | E11: =E9-E10 -> 196556.25 | F11: =F9-F10 -> 264595.94 | G11: =G9-G10 -> 356298.89
A12: 减：所得税费用 | B12: =MAX(B11,0)*假设!$C$8 -> 63750 | C12: =MAX(C11,0)*假设!$C$8 -> 49687.5 | D12: =MAX(D11,0)*假设!$C$8 -> 43656.25 | E12: =MAX(E11,0)*假设!$C$8 -> 49139.062 | F12: =MAX(F11,0)*假设!$C$8 -> 66148.984 | G12: =MAX(G11,0)*假设!$C$8 -> 89074.723
A13: 净利润 | B13: =B11-B12 -> 191250 | C13: =C11-C12 -> 149062.5 | D13: =D11-D12 -> 130968.75 | E13: =E11-E12 -> 147417.19 | F13: =F11-F12 -> 198446.95 | G13: =G11-G12 -> 267224.17
A15: 补充指标
A16: 收入同比增长率 | B16: — | C16: =C5/B5-1 -> 0.05 | D16: =D5/C5-1 -> 0.05 | E16: =E5/D5-1 -> 0.05 | F16: =F5/E5-1 -> 0.05 | G16: =G5/F5-1 -> 0.05
A17: ARPU（收入/客户数，元） | C17: =C5/C4 -> 1000 | D17: =D5/D4 -> 1000 | E17: =E5/E4 -> 1000 | F17: =F5/F4 -> 1000 | G17: =G5/G4 -> 1000
A18: 毛利率 | B18: =B6/B5 -> 0.6 | C18: =C6/C5 -> 0.6 | D18: =D6/D5 -> 0.6 | E18: =E6/E5 -> 0.6 | F18: =F6/F5 -> 0.6 | G18: =G6/G5 -> 0.6
A19: 净利率 | B19: =B13/B5 -> 0.19125 | C19: =C13/C5 -> 0.14196429 | D19: =D13/D5 -> 0.11879252 | E19: =E13/E5 -> 0.12734451 | F19: =F13/F5 -> 0.1632628 | G19: =G13/G5 -> 0.20937713

Sheet 资产负债表
A1: 星链数科 — 资产负债表（Balance Sheet）
A2: 单位：元 | 勾稽关系：总资产 = 总负债 + 总权益；现金与留存收益逐年滚动；有息负债与「支持排程」一致
A3: 项目 | B3: 2025A | C3: 2026E | D3: 2027E | E3: 2028E | F3: 2029E | G3: 2030E
A4: 资产
A5: 现金 | B5: 7000000 | C5: =B5+现金流量表!C18 -> 8644062.5 | D5: =C5+现金流量表!D18 -> 9270031.2 | E5: =D5+现金流量表!E18 -> 8912435.9 | F5: =E5+现金流量表!F18 -> 7605845.4 | G5: =F5+现金流量表!G18 -> 6367994.5
A6: 应收账款 | B6: 100000 | C6: =利润表!C5*假设!$C$12 -> 105000 | D6: =利润表!D5*假设!$C$12 -> 110250 | E6: =利润表!E5*假设!$C$12 -> 115762.5 | F6: =利润表!F5*假设!$C$12 -> 121550.62 | G6: =利润表!G5*假设!$C$12 -> 127628.16
A7: 固定资产净值（支持排程） | B7: =支持排程!B24 -> 1950000 | C7: =支持排程!C24 -> 1952500 | D7: =支持排程!D24 -> 1954875 | E7: =支持排程!E24 -> 1957131.2 | F7: =支持排程!F24 -> 1959274.7 | G7: =支持排程!G24 -> 1961311
A8: 总资产 | B8: =SUM(B5:B7) -> 9050000 | C8: =SUM(C5:C7) -> 10701562 | D8: =SUM(D5:D7) -> 11335156 | E8: =SUM(E5:E7) -> 10985330 | F8: =SUM(F5:F7) -> 9686670.7 | G8: =SUM(G5:G7) -> 8456933.6
A9: 负债
A10: 应付账款 | B10: 50000 | C10: =利润表!C5*假设!$C$13 -> 52500 | D10: =利润表!D5*假设!$C$13 -> 55125 | E10: =利润表!E5*假设!$C$13 -> 57881.25 | F10: =利润表!F5*假设!$C$13 -> 60775.312 | G10: =利润表!G5*假设!$C$13 -> 63814.078
A11: 有息负债（支持排程） | B11: =支持排程!B8 -> 2000000 | C11: =支持排程!C8 -> 3500000 | D11: =支持排程!D8 -> 4000000 | E11: =支持排程!E8 -> 3500000 | F11: =支持排程!F8 -> 2000000 | G11: =支持排程!G8 -> 500000
A12: 总负债 | B12: =B10+B11 -> 2050000 | C12: =C10+C11 -> 3552500 | D12: =D10+D11 -> 4055125 | E12: =E10+E11 -> 3557881.2 | F12: =F10+F11 -> 2060775.3 | G12: =G10+G11 -> 563814.08
A13: 权益
A14: 股本 | B14: 3000000 | C14: =B14 -> 3000000 | D14: =C14 -> 3000000 | E14: =D14 -> 3000000 | F14: =E14 -> 3000000 | G14: =F14 -> 3000000
A15: 留存收益 | B15: 4000000 | C15: =B15+利润表!C13 -> 4149062.5 | D15: =C15+利润表!D13 -> 4280031.2 | E15: =D15+利润表!E13 -> 4427448.4 | F15: =E15+利润表!F13 -> 4625895.4 | G15: =F15+利润表!G13 -> 4893119.6
A16: 总权益 | B16: =B14+B15 -> 7000000 | C16: =C14+C15 -> 7149062.5 | D16: =D14+D15 -> 7280031.2 | E16: =E14+E15 -> 7427448.4 | F16: =F14+F15 -> 7625895.4 | G16: =G14+G15 -> 7893119.6
A17: 负债和权益总计 | B17: =B12+B16 -> 9050000 | C17: =C12+C16 -> 10701562 | D17: =D12+D16 -> 11335156 | E17: =E12+E16 -> 10985330 | F17: =F12+F16 -> 9686670.7 | G17: =G12+G16 -> 8456933.6
A18: 资产负债率 | B18: =B12/B8 -> 0.22651934 | C18: =C12/C8 -> 0.33196087 | D18: =D12/D8 -> 0.3577476 | E18: =E12/E8 -> 0.32387569 | F18: =F12/F8 -> 0.21274341 | G18: =G12/G8 -> 0.066668854
A19: 勾稽校验（应始终显示“平衡”）
A20: ① 总资产 −（总负债 + 总权益） | B20: =B8-B17 -> 0 | C20: =C8-C17 -> 0 | D20: =D8-D17 -> 0 | E20: =E8-E17 -> 0 | F20: =F8-F17 -> 0 | G20: =G8-G17 -> 0
A21: ① 校验结果 | B21: =IF(ABS(B20)<0.01,"平衡","不平衡") -> 平衡 | C21: =IF(ABS(C20)<0.01,"平衡","不平衡") -> 平衡 | D21: =IF(ABS(D20)<0.01,"平衡","不平衡") -> 平衡 | E21: =IF(ABS(E20)<0.01,"平衡","不平衡") -> 平衡 | F21: =IF(ABS(F20)<0.01,"平衡","不平衡") -> 平衡 | G21: =IF(ABS(G20)<0.01,"平衡","不平衡") -> 平衡
A22: ② 本表现金 − 现金流量表期末现金 | B22: =B5-现金流量表!B20 -> 0 | C22: =C5-现金流量表!C20 -> 0 | D22: =D5-现金流量表!D20 -> 0 | E22: =E5-现金流量表!E20 -> 0 | F22: =F5-现金流量表!F20 -> 0 | G22: =G5-现金流量表!G20 -> 0
A23: ② 校验结果 | B23: =IF(ABS(B22)<0.01,"平衡","不平衡") -> 平衡 | C23: =IF(ABS(C22)<0.01,"平衡","不平衡") -> 平衡 | D23: =IF(ABS(D22)<0.01,"平衡","不平衡") -> 平衡 | E23: =IF(ABS(E22)<0.01,"平衡","不平衡") -> 平衡 | F23: =IF(ABS(F22)<0.01,"平衡","不平衡") -> 平衡 | G23: =IF(ABS(G22)<0.01,"平衡","不平衡") -> 平衡

Sheet 现金流量表
A1: 星链数科 — 现金流量表（Cash Flow Statement）
A2: 单位：元 | 间接法 | 利息当年全额付现：经营活动加回利息费用，筹资活动列示偿付利息；期末现金 = 期初现金 + 净现金流
A3: 项目 | B3: 2025A | C3: 2026E | D3: 2027E | E3: 2028E | F3: 2029E | G3: 2030E
A4: 一、经营活动
A5: 净利润 | B5: =利润表!B13 -> 191250 | C5: =利润表!C13 -> 149062.5 | D5: =利润表!D13 -> 130968.75 | E5: =利润表!E13 -> 147417.19 | F5: =利润表!F13 -> 198446.95 | G5: =利润表!G13 -> 267224.17
A6: 加：折旧（非现金费用） | B6: =利润表!B8 -> 100000 | C6: =利润表!C8 -> 97500 | D6: =利润表!D8 -> 97625 | E6: =利润表!E8 -> 97743.75 | F6: =利润表!F8 -> 97856.562 | G6: =利润表!G8 -> 97963.734
A7: 加：利息费用（付现列入筹资活动） | B7: =支持排程!B10 -> 45000 | C7: =支持排程!C10 -> 123750 | D7: =支持排程!D10 -> 168750 | E7: =支持排程!E10 -> 168750 | F7: =支持排程!F10 -> 123750 | G7: =支持排程!G10 -> 56250
A8: 营运资本变动（增加 = 现金占用） | B8: 0 | C8: =(资产负债表!C6-资产负债表!B6)-(资产负债表!C10-资产负债表!B10) -> 2500 | D8: =(资产负债表!D6-资产负债表!C6)-(资产负债表!D10-资产负债表!C10) -> 2625 | E8: =(资产负债表!E6-资产负债表!D6)-(资产负债表!E10-资产负债表!D10) -> 2756.25 | F8: =(资产负债表!F6-资产负债表!E6)-(资产负债表!F10-资产负债表!E10) -> 2894.0625 | G8: =(资产负债表!G6-资产负债表!F6)-(资产负债表!G10-资产负债表!F10) -> 3038.7656
A9: 经营活动现金流净额 | B9: =B5+B6+B7-B8 -> 336250 | C9: =C5+C6+C7-C8 -> 367812.5 | D9: =D5+D6+D7-D8 -> 394718.75 | E9: =E5+E6+E7-E8 -> 411154.69 | F9: =F5+F6+F7-F8 -> 417159.45 | G9: =G5+G6+G7-G8 -> 418399.14
A10: 二、投资活动
A11: 资本支出 | B11: -100000 | C11: =-假设!$C$11 -> -100000 | D11: =-假设!$C$11 -> -100000 | E11: =-假设!$C$11 -> -100000 | F11: =-假设!$C$11 -> -100000 | G11: =-假设!$C$11 -> -100000
A12: 投资活动现金流净额 | B12: =B11 -> -100000 | C12: =C11 -> -100000 | D12: =D11 -> -100000 | E12: =E11 -> -100000 | F12: =F11 -> -100000 | G12: =G11 -> -100000
A13: 三、融资活动
A14: 新增借款收到的现金 | B14: 2000000 | C14: =支持排程!C6 -> 1500000 | D14: =支持排程!D6 -> 1000000 | E14: =支持排程!E6 -> 500000 | F14: =支持排程!F6 -> 0 | G14: =支持排程!G6 -> 0
A15: 偿还债务支付的现金 | B15: 0 | C15: =-支持排程!C7 -> 0 | D15: =-支持排程!D7 -> -500000 | E15: =-支持排程!E7 -> -1000000 | F15: =-支持排程!F7 -> -1500000 | G15: =-支持排程!G7 -> -1500000
A16: 偿付利息支付的现金 | B16: =-支持排程!B10 -> -45000 | C16: =-支持排程!C10 -> -123750 | D16: =-支持排程!D10 -> -168750 | E16: =-支持排程!E10 -> -168750 | F16: =-支持排程!F10 -> -123750 | G16: =-支持排程!G10 -> -56250
A17: 融资活动现金流净额 | B17: =SUM(B14:B16) -> 1955000 | C17: =SUM(C14:C16) -> 1376250 | D17: =SUM(D14:D16) -> 331250 | E17: =SUM(E14:E16) -> -668750 | F17: =SUM(F14:F16) -> -1623750 | G17: =SUM(G14:G16) -> -1556250
A18: 现金及现金等价物净增加额 | B18: =B9+B12+B17 -> 2191250 | C18: =C9+C12+C17 -> 1644062.5 | D18: =D9+D12+D17 -> 625968.75 | E18: =E9+E12+E17 -> -357595.31 | F18: =F9+F12+F17 -> -1306590.5 | G18: =G9+G12+G17 -> -1237850.9
A19: 期初现金 | B19: 4808750 | C19: =资产负债表!B5 -> 7000000 | D19: =资产负债表!C5 -> 8644062.5 | E19: =资产负债表!D5 -> 9270031.2 | F19: =资产负债表!E5 -> 8912435.9 | G19: =资产负债表!F5 -> 7605845.4
A20: 期末现金 | B20: =B19+B18 -> 7000000 | C20: =C19+C18 -> 8644062.5 | D20: =D19+D18 -> 9270031.2 | E20: =E19+E18 -> 8912435.9 | F20: =F19+F18 -> 7605845.4 | G20: =G19+G18 -> 6367994.5
A21: 补充：自由现金流（经营+投资） | B21: =B9+B12 -> 236250 | C21: =C9+C12 -> 267812.5 | D21: =D9+D12 -> 294718.75 | E21: =E9+E12 -> 311154.69 | F21: =F9+F12 -> 317159.45 | G21: =G9+G12 -> 318399.14
A22: 现金安全线 | B22: =假设!$C$14 -> 4000000 | C22: =假设!$C$14 -> 4000000 | D22: =假设!$C$14 -> 4000000 | E22: =假设!$C$14 -> 4000000 | F22: =假设!$C$14 -> 4000000 | G22: =假设!$C$14 -> 4000000
A23: 低于安全线标记（1 = 是） | B23: =IF(B20<B22,1,0) -> 0 | C23: =IF(C20<C22,1,0) -> 0 | D23: =IF(D20<D22,1,0) -> 0 | E23: =IF(E20<E22,1,0) -> 0 | F23: =IF(F20<F22,1,0) -> 0 | G23: =IF(G20<G22,1,0) -> 0
A24: 注：B7/B8/B14/B15/B19 为基年实际数（蓝色）；2025A 利息按期初（0）与期末（200 万）负债的平均余额计提，融资活动含当年新增借款 200 万元——净利润、筹资现金流与资产负债表现金完整勾稽。营运资本变动 = Δ应收 − Δ应付，正数表示现金被占用（间接法中为减项）。

Sheet 支持排程
A1: 星链数科 — 支持排程（债务排程 + 固定资产排程）
A2: 单位：元 | 债务：期末 = 期初 + 新增 − 偿还；利息 = 平均余额 × 利率（假设 A-11） | 固定资产：折旧按期初净值计提，以期初净值为上限
A3: 项目 | B3: 2025A | C3: 2026E | D3: 2027E | E3: 2028E | F3: 2029E | G3: 2030E
A4: 一、债务排程（有息负债 · 蓝色为融资计划输入）
A5: 期初有息负债 | B5: 0 | C5: =B8 -> 2000000 | D5: =C8 -> 3500000 | E5: =D8 -> 4000000 | F5: =E8 -> 3500000 | G5: =F8 -> 2000000
A6: 新增借款（输入） | B6: 2000000 | C6: 1500000 | D6: 1000000 | E6: 500000 | F6: 0 | G6: 0
A7: 偿还本金（输入） | B7: 0 | C7: 0 | D7: 500000 | E7: 1000000 | F7: 1500000 | G7: 1500000
A8: 期末有息负债 | B8: =B5+B6-B7 -> 2000000 | C8: =C5+C6-C7 -> 3500000 | D8: =D5+D6-D7 -> 4000000 | E8: =E5+E6-E7 -> 3500000 | F8: =F5+F6-F7 -> 2000000 | G8: =G5+G6-G7 -> 500000
A9: 平均有息负债 | B9: =(B5+B8)/2 -> 1000000 | C9: =(C5+C8)/2 -> 2750000 | D9: =(D5+D8)/2 -> 3750000 | E9: =(E5+E8)/2 -> 3750000 | F9: =(F5+F8)/2 -> 2750000 | G9: =(G5+G8)/2 -> 1250000
A10: 利息费用（平均余额×年利率） | B10: =B9*假设!$C$15 -> 45000 | C10: =C9*假设!$C$15 -> 123750 | D10: =D9*假设!$C$15 -> 168750 | E10: =E9*假设!$C$15 -> 168750 | F10: =F9*假设!$C$15 -> 123750 | G10: =G9*假设!$C$15 -> 56250
A11: 负债余额非负校验 | B11: =IF(B8<-0.01,"✗","✓") -> ✓ | C11: =IF(C8<-0.01,"✗","✓") -> ✓ | D11: =IF(D8<-0.01,"✗","✓") -> ✓ | E11: =IF(E8<-0.01,"✗","✓") -> ✓ | F11: =IF(F8<-0.01,"✗","✓") -> ✓ | G11: =IF(G8<-0.01,"✗","✓") -> ✓
A13: 二、偿债能力与回报指标（自动计算）
A14: 资产负债率（含负债） | B14: =资产负债表!B12/资产负债表!B8 -> 0.22651934 | C14: =资产负债表!C12/资产负债表!C8 -> 0.33196087 | D14: =资产负债表!D12/资产负债表!D8 -> 0.3577476 | E14: =资产负债表!E12/资产负债表!E8 -> 0.32387569 | F14: =资产负债表!F12/资产负债表!F8 -> 0.21274341 | G14: =资产负债表!G12/资产负债表!G8 -> 0.066668854
A15: 有息负债 / 总权益 | B15: =B8/资产负债表!B16 -> 0.28571429 | C15: =C8/资产负债表!C16 -> 0.48957468 | D15: =D8/资产负债表!D16 -> 0.54944819 | E15: =E8/资产负债表!E16 -> 0.47122508 | F15: =F8/资产负债表!F16 -> 0.26226428 | G15: =G8/资产负债表!G16 -> 0.06334631
A16: 利息保障倍数（EBIT / 利息费用） | B16: =IF(B10>0.001,利润表!B9/B10,"n.a.") -> 6.6666667 | C16: =IF(C10>0.001,利润表!C9/C10,"n.a.") -> 2.6060606 | D16: =IF(D10>0.001,利润表!D9/D10,"n.a.") -> 2.0348148 | E16: =IF(E10>0.001,利润表!E9/E10,"n.a.") -> 2.1647778 | F16: =IF(F10>0.001,利润表!F9/F10,"n.a.") -> 3.138149 | G16: =IF(G10>0.001,利润表!G9/G10,"n.a.") -> 7.3342025
A17: ROIC（EBIT×(1−税率) / 投入资本） | B17: =利润表!B9*(1-假设!$C$8)/(B8+资产负债表!B16-资产负债表!B5) -> 0.1125 | C17: =利润表!C9*(1-假设!$C$8)/(C8+资产负债表!C16-资产负债表!C5) -> 0.12063591 | D17: =利润表!D9*(1-假设!$C$8)/(D8+资产负债表!D16-资产负债表!D5) -> 0.128125 | E17: =利润表!E9*(1-假设!$C$8)/(E8+资产负债表!E16-资产负债表!E5) -> 0.13596922 | F17: =利润表!F9*(1-假设!$C$8)/(F8+资产负债表!F16-资产负债表!F5) -> 0.14418428 | G17: =利润表!G9*(1-假设!$C$8)/(G8+资产负债表!G16-资产负债表!G5) -> 0.15278645
A18: 三、固定资产排程（折旧按净值计提，以期初净值为上限，不会折成负值）
A19: 期初固定资产原值 | B19: 2500000 | C19: =B21 -> 2600000 | D19: =C21 -> 2700000 | E19: =D21 -> 2800000 | F19: =E21 -> 2900000 | G19: =F21 -> 3000000
A20: 加：本年资本支出 | B20: 100000 | C20: =假设!$C$11 -> 100000 | D20: =假设!$C$11 -> 100000 | E20: =假设!$C$11 -> 100000 | F20: =假设!$C$11 -> 100000 | G20: =假设!$C$11 -> 100000
A21: 期末固定资产原值 | B21: =B19+B20 -> 2600000 | C21: =C19+C20 -> 2700000 | D21: =D19+D20 -> 2800000 | E21: =E19+E20 -> 2900000 | F21: =F19+F20 -> 3000000 | G21: =G19+G20 -> 3100000
A22: 期初固定资产净值 | B22: 1950000 | C22: =B24 -> 1950000 | D22: =C24 -> 1952500 | E22: =D24 -> 1954875 | F22: =E24 -> 1957131.2 | G22: =F24 -> 1959274.7
A23: 本年折旧（=MIN(期初净值×折旧率, 期初净值)） | B23: 100000 | C23: =MIN(C22*假设!$C$16,C22) -> 97500 | D23: =MIN(D22*假设!$C$16,D22) -> 97625 | E23: =MIN(E22*假设!$C$16,E22) -> 97743.75 | F23: =MIN(F22*假设!$C$16,F22) -> 97856.562 | G23: =MIN(G22*假设!$C$16,G22) -> 97963.734
A24: 期末固定资产净值 | B24: =B22+B20-B23 -> 1950000 | C24: =C22+C20-C23 -> 1952500 | D24: =D22+D20-D23 -> 1954875 | E24: =E22+E20-E23 -> 1957131.2 | F24: =F22+F20-F23 -> 1959274.7 | G24: =G22+G20-G23 -> 1961311
A25: 累计折旧（=期末原值−期末净值） | B25: =B21-B24 -> 650000 | C25: =C21-C24 -> 747500 | D25: =D21-D24 -> 845125 | E25: =E21-E24 -> 942868.75 | F25: =F21-F24 -> 1040725.3 | G25: =G21-G24 -> 1138689
A27: 注1：利息 = 平均有息负债 × 年利率（「假设」页 A-11）——新增借款自放入年起即按平均余额生息；平均余额法下当年新增借款按半年计息（偏乐观），如需更保守可将平均余额改为期末余额；利息全额付现，无应付利息挂账。
A28: 注2：利息付现列入筹资活动“偿付利息支付的现金”，同时在经营活动加回利息费用，两者对消；净利润已含利息税盾 → 不存在“利息←负债←现金”循环引用。
A29: 注3：固定资产折旧按期初净值 × 折旧率（A-12）计提，并以期初净值为上限（MIN），期末净值不会为负；资本支出同时计入原值与净值。
A30: 注4：2026E–2030E 融资计划（蓝色输入）：新增借款合计 300 万、偿还合计 450 万，2030E 末保留 50 万借款余额；改蓝色单元格，利息/偿债指标/三表同步联动。
A31: 注5：投入资本 = 有息负债 + 总权益 − 现金；ROIC 与 DCF 互为补充——DCF 回答“公司值多少钱”，ROIC 回答“每一块投入资本赚回多少”，两者合看才是完整的资本配置视角。

Sheet 图表
A1: 星链数科 — 图表（随「假设」页情景自动更新）
A2: 图1：收入与净利润｜图2：经营现金流与期末现金｜图3：现金跑道（期末现金 vs 安全线）｜图4：有息负债余额与利息费用
A82: 注：图3 中红线 = 现金安全线（「假设」页 A-10）；若期末现金折线跌破红线，说明需提前规划融资。图4 展示债务排程：借款高峰后逐年偿还，利息费用随平均余额同步回落。

Sheet 敏感性分析
A1: 星链数科 — 估值与敏感性分析
A2: 单位：元 | 估值使用假设面板折现率；无杠杆自由现金流口径；敏感性为解析解，并与模型实时勾稽校验
A4: 一、简化 DCF 估值（无杠杆自由现金流）
A5: 项目 | B5: 2025A | C5: 2026E | D5: 2027E | E5: 2028E | F5: 2029E | G5: 2030E
A6: 自由现金流（经营+投资−利息税盾） | B6: — | C6: =现金流量表!C9+现金流量表!C12-支持排程!C10*假设!$C$8 -> 236875 | D6: =现金流量表!D9+现金流量表!D12-支持排程!D10*假设!$C$8 -> 252531.25 | E6: =现金流量表!E9+现金流量表!E12-支持排程!E10*假设!$C$8 -> 268967.19 | F6: =现金流量表!F9+现金流量表!F12-支持排程!F10*假设!$C$8 -> 286221.95 | G6: =现金流量表!G9+现金流量表!G12-支持排程!G10*假设!$C$8 -> 304336.64
A7: 折现因子 | B7: — | C7: =1/(1+假设!$C$9)^1 -> 0.90909091 | D7: =1/(1+假设!$C$9)^2 -> 0.82644628 | E7: =1/(1+假设!$C$9)^3 -> 0.7513148 | F7: =1/(1+假设!$C$9)^4 -> 0.68301346 | G7: =1/(1+假设!$C$9)^5 -> 0.62092132
A8: 现金流现值 | B8: — | C8: =C6*C7 -> 215340.91 | D8: =D6*D7 -> 208703.51 | E8: =E6*E7 -> 202079.03 | F8: =F6*F7 -> 195493.45 | G8: =G6*G7 -> 188969.11
A10: 预测期现值合计（2026E–2030E） | C10: =SUM(C8:G8) -> 1010586
A11: 终值（永续增长法，g = 收入增长率） | C11: =IF(假设!$C$9<=假设!$C$5,"n.a.（折现率≤增长率）",G6*(1+假设!$C$5)/(假设!$C$9-假设!$C$5)) -> 6391069.4
A12: 终值现值 | C12: =IF(ISNUMBER($C$11),$G$7*$C$11,0) -> 3968351.2
A13: 企业价值（经营价值） | C13: =$C$10+$C$12 -> 4978937.3
A14: 加：基年净现金（现金 − 有息负债） | C14: =资产负债表!$B$5-支持排程!$B$8 -> 5000000
A15: 股权价值（简化） | C15: =$C$13+$C$14 -> 9978937.3
A16: 注：FCF 剔除利息税盾后为无杠杆口径（经营 + 投资 − 利息费用×税率）；终值假设 5 年后永续增长率 = 当前收入增长率（Base 5%）——对成熟期公司建议将终值增长率下调至 2%–3%，本模型为简化处理；2025A 末有息负债 200 万元，股权价值 = 企业价值 + 基年现金 − 有息负债。估值仅供参考。
A18: 二、敏感性分析①：5 年累计净利润（2026E–2030E，元）
A19: 行 = 收入增长率，列 = 毛利率；蓝色行列头带数据验证，可修改后自动重算。
A20: 增长率＼毛利率 | B20: 0.5 | C20: 0.55 | D20: 0.6 | E20: 0.65 | F20: 0.7
A21: 0.03 | B21: =(1-假设!$C$8)*((B$20*利润表!$B$5-假设!$C$7*假设!$C$10)*IF($A21=0,5,(1+$A21)*((1+$A21)^5-1)/$A21)-SUM(支持排程!$C$23:$G$23)-SUM(支持排程!$C$10:$G$10)) -> 382937.94 | C21: =(1-假设!$C$8)*((C$20*利润表!$B$5-假设!$C$7*假设!$C$10)*IF($A21=0,5,(1+$A21)*((1+$A21)^5-1)/$A21)-SUM(支持排程!$C$23:$G$23)-SUM(支持排程!$C$10:$G$10)) -> 588003.31 | D21: =(1-假设!$C$8)*((D$20*利润表!$B$5-假设!$C$7*假设!$C$10)*IF($A21=0,5,(1+$A21)*((1+$A21)^5-1)/$A21)-SUM(支持排程!$C$23:$G$23)-SUM(支持排程!$C$10:$G$10)) -> 793068.68 | E21: =(1-假设!$C$8)*((E$20*利润表!$B$5-假设!$C$7*假设!$C$10)*IF($A21=0,5,(1+$A21)*((1+$A21)^5-1)/$A21)-SUM(支持排程!$C$23:$G$23)-SUM(支持排程!$C$10:$G$10)) -> 998134.05 | F21: =(1-假设!$C$8)*((F$20*利润表!$B$5-假设!$C$7*假设!$C$10)*IF($A21=0,5,(1+$A21)*((1+$A21)^5-1)/$A21)-SUM(支持排程!$C$23:$G$23)-SUM(支持排程!$C$10:$G$10)) -> 1203199.4
A22: 0.05 | B22: =(1-假设!$C$8)*((B$20*利润表!$B$5-假设!$C$7*假设!$C$10)*IF($A22=0,5,(1+$A22)*((1+$A22)^5-1)/$A22)-SUM(支持排程!$C$23:$G$23)-SUM(支持排程!$C$10:$G$10)) -> 457976.1 | C22: =(1-假设!$C$8)*((C$20*利润表!$B$5-假设!$C$7*假设!$C$10)*IF($A22=0,5,(1+$A22)*((1+$A22)^5-1)/$A22)-SUM(支持排程!$C$23:$G$23)-SUM(支持排程!$C$10:$G$10)) -> 675547.83 | D22: =(1-假设!$C$8)*((D$20*利润表!$B$5-假设!$C$7*假设!$C$10)*IF($A22=0,5,(1+$A22)*((1+$A22)^5-1)/$A22)-SUM(支持排程!$C$23:$G$23)-SUM(支持排程!$C$10:$G$10)) -> 893119.56 | E22: =(1-假设!$C$8)*((E$20*利润表!$B$5-假设!$C$7*假设!$C$10)*IF($A22=0,5,(1+$A22)*((1+$A22)^5-1)/$A22)-SUM(支持排程!$C$23:$G$23)-SUM(支持排程!$C$10:$G$10)) -> 1110691.3 | F22: =(1-假设!$C$8)*((F$20*利润表!$B$5-假设!$C$7*假设!$C$10)*IF($A22=0,5,(1+$A22)*((1+$A22)^5-1)/$A22)-SUM(支持排程!$C$23:$G$23)-SUM(支持排程!$C$10:$G$10)) -> 1328263
A23: 0.08 | B23: =(1-假设!$C$8)*((B$20*利润表!$B$5-假设!$C$7*假设!$C$10)*IF($A23=0,5,(1+$A23)*((1+$A23)^5-1)/$A23)-SUM(支持排程!$C$23:$G$23)-SUM(支持排程!$C$10:$G$10)) -> 578129.75 | C23: =(1-假设!$C$8)*((C$20*利润表!$B$5-假设!$C$7*假设!$C$10)*IF($A23=0,5,(1+$A23)*((1+$A23)^5-1)/$A23)-SUM(支持排程!$C$23:$G$23)-SUM(支持排程!$C$10:$G$10)) -> 815727.09 | D23: =(1-假设!$C$8)*((D$20*利润表!$B$5-假设!$C$7*假设!$C$10)*IF($A23=0,5,(1+$A23)*((1+$A23)^5-1)/$A23)-SUM(支持排程!$C$23:$G$23)-SUM(支持排程!$C$10:$G$10)) -> 1053324.4 | E23: =(1-假设!$C$8)*((E$20*利润表!$B$5-假设!$C$7*假设!$C$10)*IF($A23=0,5,(1+$A23)*((1+$A23)^5-1)/$A23)-SUM(支持排程!$C$23:$G$23)-SUM(支持排程!$C$10:$G$10)) -> 1290921.8 | F23: =(1-假设!$C$8)*((F$20*利润表!$B$5-假设!$C$7*假设!$C$10)*IF($A23=0,5,(1+$A23)*((1+$A23)^5-1)/$A23)-SUM(支持排程!$C$23:$G$23)-SUM(支持排程!$C$10:$G$10)) -> 1528519.1
A24: 0.1 | B24: =(1-假设!$C$8)*((B$20*利润表!$B$5-假设!$C$7*假设!$C$10)*IF($A24=0,5,(1+$A24)*((1+$A24)^5-1)/$A24)-SUM(支持排程!$C$23:$G$23)-SUM(支持排程!$C$10:$G$10)) -> 663557.96 | C24: =(1-假设!$C$8)*((C$20*利润表!$B$5-假设!$C$7*假设!$C$10)*IF($A24=0,5,(1+$A24)*((1+$A24)^5-1)/$A24)-SUM(支持排程!$C$23:$G$23)-SUM(支持排程!$C$10:$G$10)) -> 915393.34 | D24: =(1-假设!$C$8)*((D$20*利润表!$B$5-假设!$C$7*假设!$C$10)*IF($A24=0,5,(1+$A24)*((1+$A24)^5-1)/$A24)-SUM(支持排程!$C$23:$G$23)-SUM(支持排程!$C$10:$G$10)) -> 1167228.7 | E24: =(1-假设!$C$8)*((E$20*利润表!$B$5-假设!$C$7*假设!$C$10)*IF($A24=0,5,(1+$A24)*((1+$A24)^5-1)/$A24)-SUM(支持排程!$C$23:$G$23)-SUM(支持排程!$C$10:$G$10)) -> 1419064.1 | F24: =(1-假设!$C$8)*((F$20*利润表!$B$5-假设!$C$7*假设!$C$10)*IF($A24=0,5,(1+$A24)*((1+$A24)^5-1)/$A24)-SUM(支持排程!$C$23:$G$23)-SUM(支持排程!$C$10:$G$10)) -> 1670899.5
A25: 0.15 | B25: =(1-假设!$C$8)*((B$20*利润表!$B$5-假设!$C$7*假设!$C$10)*IF($A25=0,5,(1+$A25)*((1+$A25)^5-1)/$A25)-SUM(支持排程!$C$23:$G$23)-SUM(支持排程!$C$10:$G$10)) -> 897136.86 | C25: =(1-假设!$C$8)*((C$20*利润表!$B$5-假设!$C$7*假设!$C$10)*IF($A25=0,5,(1+$A25)*((1+$A25)^5-1)/$A25)-SUM(支持排程!$C$23:$G$23)-SUM(支持排程!$C$10:$G$10)) -> 1187902.1 | D25: =(1-假设!$C$8)*((D$20*利润表!$B$5-假设!$C$7*假设!$C$10)*IF($A25=0,5,(1+$A25)*((1+$A25)^5-1)/$A25)-SUM(支持排程!$C$23:$G$23)-SUM(支持排程!$C$10:$G$10)) -> 1478667.2 | E25: =(1-假设!$C$8)*((E$20*利润表!$B$5-假设!$C$7*假设!$C$10)*IF($A25=0,5,(1+$A25)*((1+$A25)^5-1)/$A25)-SUM(支持排程!$C$23:$G$23)-SUM(支持排程!$C$10:$G$10)) -> 1769432.4 | F25: =(1-假设!$C$8)*((F$20*利润表!$B$5-假设!$C$7*假设!$C$10)*IF($A25=0,5,(1+$A25)*((1+$A25)^5-1)/$A25)-SUM(支持排程!$C$23:$G$23)-SUM(支持排程!$C$10:$G$10)) -> 2060197.6
A26: 勾稽校验（当前情景） | B26: =IF(IFERROR(ABS(INDEX($B$21:$F$25,MATCH(假设!$C$5,$A$21:$A$25,0),MATCH(假设!$C$6,$B$20:$F$20,0))-SUM(利润表!$C$13:$G$13)),1)<1,"✓ 与利润表 5 年净利润合计勾稽一致","✗ 与模型不一致（或当前情景不在表中）") -> ✓ 与利润表 5 年净利润合计勾稽一致
A27: 注：解析解假设各年税前利润为正；5 年折旧与 5 年利息直接取自「支持排程」当期计划（与增长率、毛利率无关）。本表隐含 CapEx 与融资计划不随增长率变化（折旧、利息为固定值）、ARPU 稳定（客户数增速 = 收入增速）；若高增长需要额外 CapEx / 融资，实际利润增幅会低于本表。
A29: 三、敏感性分析②：2030E 期末现金（元）
A30: 行 = 收入增长率；蓝色行头带数据验证，可修改后自动重算。
A31: 收入增长率 | B31: 2030E 期末现金
A32: 0.03 | B32: =资产负债表!$B$5+(1-假设!$C$8)*((假设!$C$6*利润表!$B$5-假设!$C$7*假设!$C$10)*IF($A32=0,5,(1+$A32)*((1+$A32)^5-1)/$A32)-SUM(支持排程!$C$23:$G$23)-SUM(支持排程!$C$10:$G$10))+SUM(支持排程!$C$23:$G$23)-(假设!$C$12-假设!$C$13)*利润表!$B$5*(1+$A32)^5+(资产负债表!$B$6-资产负债表!$B$10)-SUM(支持排程!$C$20:$G$20)+SUM(支持排程!$C$6:$G$6)-SUM(支持排程!$C$7:$G$7) -> 6273794
A33: 0.05 | B33: =资产负债表!$B$5+(1-假设!$C$8)*((假设!$C$6*利润表!$B$5-假设!$C$7*假设!$C$10)*IF($A33=0,5,(1+$A33)*((1+$A33)^5-1)/$A33)-SUM(支持排程!$C$23:$G$23)-SUM(支持排程!$C$10:$G$10))+SUM(支持排程!$C$23:$G$23)-(假设!$C$12-假设!$C$13)*利润表!$B$5*(1+$A33)^5+(资产负债表!$B$6-资产负债表!$B$10)-SUM(支持排程!$C$20:$G$20)+SUM(支持排程!$C$6:$G$6)-SUM(支持排程!$C$7:$G$7) -> 6367994.5
A34: 0.08 | B34: =资产负债表!$B$5+(1-假设!$C$8)*((假设!$C$6*利润表!$B$5-假设!$C$7*假设!$C$10)*IF($A34=0,5,(1+$A34)*((1+$A34)^5-1)/$A34)-SUM(支持排程!$C$23:$G$23)-SUM(支持排程!$C$10:$G$10))+SUM(支持排程!$C$23:$G$23)-(假设!$C$12-假设!$C$13)*利润表!$B$5*(1+$A34)^5+(资产负债表!$B$6-资产负债表!$B$10)-SUM(支持排程!$C$20:$G$20)+SUM(支持排程!$C$6:$G$6)-SUM(支持排程!$C$7:$G$7) -> 6518547.1
A35: 0.1 | B35: =资产负债表!$B$5+(1-假设!$C$8)*((假设!$C$6*利润表!$B$5-假设!$C$7*假设!$C$10)*IF($A35=0,5,(1+$A35)*((1+$A35)^5-1)/$A35)-SUM(支持排程!$C$23:$G$23)-SUM(支持排程!$C$10:$G$10))+SUM(支持排程!$C$23:$G$23)-(假设!$C$12-假设!$C$13)*利润表!$B$5*(1+$A35)^5+(资产负债表!$B$6-资产负债表!$B$10)-SUM(支持排程!$C$20:$G$20)+SUM(支持排程!$C$6:$G$6)-SUM(支持排程!$C$7:$G$7) -> 6625392.3
A36: 0.15 | B36: =资产负债表!$B$5+(1-假设!$C$8)*((假设!$C$6*利润表!$B$5-假设!$C$7*假设!$C$10)*IF($A36=0,5,(1+$A36)*((1+$A36)^5-1)/$A36)-SUM(支持排程!$C$23:$G$23)-SUM(支持排程!$C$10:$G$10))+SUM(支持排程!$C$23:$G$23)-(假设!$C$12-假设!$C$13)*利润表!$B$5*(1+$A36)^5+(资产负债表!$B$6-资产负债表!$B$10)-SUM(支持排程!$C$20:$G$20)+SUM(支持排程!$C$6:$G$6)-SUM(支持排程!$C$7:$G$7) -> 6916788.4
A37: 勾稽校验（当前情景） | B37: =IF(IFERROR(ABS(INDEX($B$32:$B$36,MATCH(假设!$C$5,$A$32:$A$36,0))-资产负债表!$G$5),1)<1,"✓ 与资产负债表 2030E 现金勾稽一致","✗ 与模型不一致（或当前情景不在表中）") -> ✓ 与资产负债表 2030E 现金勾稽一致
A38: 注：期末现金 = 基年现金 + 5 年累计净利润 + 5 年折旧 − 营运资本累计变动 − 5 年资本支出 + 5 年新增借款 − 5 年偿还本金（利息影响已含在净利润，经营加回与筹资付现对消）。
A40: 四、边际敏感度：收入增长率每 ±1 个百分点的影响
A41: 当前增长率 g | C41: =假设!$C$5 -> 0.05
A42: g + 1pp | C42: =C41+0.01 -> 0.06
A43: 当前 g 的 5 年累计净利润（元） | C43: =(1-假设!$C$8)*((假设!$C$6*利润表!$B$5-假设!$C$7*假设!$C$10)*IF($C$41=0,5,(1+$C$41)*((1+$C$41)^5-1)/$C$41)-SUM(支持排程!$C$23:$G$23)-SUM(支持排程!$C$10:$G$10)) -> 893119.56
A44: g + 1pp 的 5 年累计净利润（元） | C44: =(1-假设!$C$8)*((假设!$C$6*利润表!$B$5-假设!$C$7*假设!$C$10)*IF($C$42=0,5,(1+$C$42)*((1+$C$42)^5-1)/$C$42)-SUM(支持排程!$C$23:$G$23)-SUM(支持排程!$C$10:$G$10)) -> 945141.28
A45: 边际影响（万元 / 每 1pp） | C45: =(C44-C43)/10000 -> 5.2021718
...
